executor.py [LINE:362] #INFO     [2025-03-27 23:47:57,392]  Bot: Заявка в ИИС [@request_to_IIS_bot]
dispatcher.py [LINE:359] #INFO     [2025-03-27 23:47:57,708]  Start polling.
dispatcher.py [LINE:391] #ERROR    [2025-04-01 11:47:47,896]  Cause exception while getting updates.
Traceback (most recent call last):
  File "/usr/local/lib/python3.10/site-packages/aiogram/dispatcher/dispatcher.py", line 382, in start_polling
    updates = await self.bot.get_updates(
  File "/usr/local/lib/python3.10/site-packages/aiogram/bot/bot.py", line 110, in get_updates
    result = await self.request(api.Methods.GET_UPDATES, payload)
  File "/usr/local/lib/python3.10/site-packages/aiogram/bot/base.py", line 236, in request
    return await api.make_request(await self.get_session(), self.server, self.__token, method, data, files,
  File "/usr/local/lib/python3.10/site-packages/aiogram/bot/api.py", line 139, in make_request
    async with session.post(url, data=req, **kwargs) as response:
  File "/usr/local/lib/python3.10/site-packages/aiohttp/client.py", line 1167, in __aenter__
    self._resp = await self._coro
  File "/usr/local/lib/python3.10/site-packages/aiohttp/client.py", line 586, in _request
    await resp.start(conn)
  File "/usr/local/lib/python3.10/site-packages/aiohttp/client_reqrep.py", line 900, in start
    with self._timer:
  File "/usr/local/lib/python3.10/site-packages/aiohttp/helpers.py", line 725, in __exit__
    raise asyncio.TimeoutError from None
asyncio.exceptions.TimeoutError
mysqlrequests.py [LINE:74] #INFO     [2025-04-02 07:23:51,175]  Ошибка запроса sql: (1406, "Data too long for column 'full_name' at row 1")
dispatcher.py [LINE:391] #ERROR    [2025-04-02 10:04:08,942]  Cause exception while getting updates.
Traceback (most recent call last):
  File "/usr/local/lib/python3.10/site-packages/aiogram/dispatcher/dispatcher.py", line 382, in start_polling
    updates = await self.bot.get_updates(
  File "/usr/local/lib/python3.10/site-packages/aiogram/bot/bot.py", line 110, in get_updates
    result = await self.request(api.Methods.GET_UPDATES, payload)
  File "/usr/local/lib/python3.10/site-packages/aiogram/bot/base.py", line 236, in request
    return await api.make_request(await self.get_session(), self.server, self.__token, method, data, files,
  File "/usr/local/lib/python3.10/site-packages/aiogram/bot/api.py", line 139, in make_request
    async with session.post(url, data=req, **kwargs) as response:
  File "/usr/local/lib/python3.10/site-packages/aiohttp/client.py", line 1167, in __aenter__
    self._resp = await self._coro
  File "/usr/local/lib/python3.10/site-packages/aiohttp/client.py", line 586, in _request
    await resp.start(conn)
  File "/usr/local/lib/python3.10/site-packages/aiohttp/client_reqrep.py", line 900, in start
    with self._timer:
  File "/usr/local/lib/python3.10/site-packages/aiohttp/helpers.py", line 725, in __exit__
    raise asyncio.TimeoutError from None
asyncio.exceptions.TimeoutError
dispatcher.py [LINE:391] #ERROR    [2025-04-03 14:53:11,984]  Cause exception while getting updates.
Traceback (most recent call last):
  File "/usr/local/lib/python3.10/site-packages/aiogram/dispatcher/dispatcher.py", line 382, in start_polling
    updates = await self.bot.get_updates(
  File "/usr/local/lib/python3.10/site-packages/aiogram/bot/bot.py", line 110, in get_updates
    result = await self.request(api.Methods.GET_UPDATES, payload)
  File "/usr/local/lib/python3.10/site-packages/aiogram/bot/base.py", line 236, in request
    return await api.make_request(await self.get_session(), self.server, self.__token, method, data, files,
  File "/usr/local/lib/python3.10/site-packages/aiogram/bot/api.py", line 139, in make_request
    async with session.post(url, data=req, **kwargs) as response:
  File "/usr/local/lib/python3.10/site-packages/aiohttp/client.py", line 1167, in __aenter__
    self._resp = await self._coro
  File "/usr/local/lib/python3.10/site-packages/aiohttp/client.py", line 586, in _request
    await resp.start(conn)
  File "/usr/local/lib/python3.10/site-packages/aiohttp/client_reqrep.py", line 900, in start
    with self._timer:
  File "/usr/local/lib/python3.10/site-packages/aiohttp/helpers.py", line 725, in __exit__
    raise asyncio.TimeoutError from None
asyncio.exceptions.TimeoutError
dispatcher.py [LINE:391] #ERROR    [2025-04-03 14:53:24,992]  Cause exception while getting updates.
Traceback (most recent call last):
  File "/usr/local/lib/python3.10/site-packages/aiohttp/connector.py", line 1155, in _create_direct_connection
    hosts = await asyncio.shield(host_resolved)
  File "/usr/local/lib/python3.10/site-packages/aiohttp/connector.py", line 874, in _resolve_host
    addrs = await self._resolver.resolve(host, port, family=self._family)
  File "/usr/local/lib/python3.10/site-packages/aiohttp/resolver.py", line 33, in resolve
    infos = await self._loop.getaddrinfo(
  File "/usr/local/lib/python3.10/asyncio/base_events.py", line 860, in getaddrinfo
    return await self.run_in_executor(
  File "/usr/local/lib/python3.10/concurrent/futures/thread.py", line 58, in run
    result = self.fn(*self.args, **self.kwargs)
  File "/usr/local/lib/python3.10/socket.py", line 955, in getaddrinfo
    for res in _socket.getaddrinfo(host, port, family, type, proto, flags):
socket.gaierror: [Errno -3] Temporary failure in name resolution

The above exception was the direct cause of the following exception:

Traceback (most recent call last):
  File "/usr/local/lib/python3.10/site-packages/aiogram/bot/api.py", line 139, in make_request
    async with session.post(url, data=req, **kwargs) as response:
  File "/usr/local/lib/python3.10/site-packages/aiohttp/client.py", line 1167, in __aenter__
    self._resp = await self._coro
  File "/usr/local/lib/python3.10/site-packages/aiohttp/client.py", line 562, in _request
    conn = await self._connector.connect(
  File "/usr/local/lib/python3.10/site-packages/aiohttp/connector.py", line 540, in connect
    proto = await self._create_connection(req, traces, timeout)
  File "/usr/local/lib/python3.10/site-packages/aiohttp/connector.py", line 901, in _create_connection
    _, proto = await self._create_direct_connection(req, traces, timeout)
  File "/usr/local/lib/python3.10/site-packages/aiohttp/connector.py", line 1169, in _create_direct_connection
    raise ClientConnectorError(req.connection_key, exc) from exc
aiohttp.client_exceptions.ClientConnectorError: Cannot connect to host api.telegram.org:443 ssl:default [Temporary failure in name resolution]

During handling of the above exception, another exception occurred:

Traceback (most recent call last):
  File "/usr/local/lib/python3.10/site-packages/aiogram/dispatcher/dispatcher.py", line 382, in start_polling
    updates = await self.bot.get_updates(
  File "/usr/local/lib/python3.10/site-packages/aiogram/bot/bot.py", line 110, in get_updates
    result = await self.request(api.Methods.GET_UPDATES, payload)
  File "/usr/local/lib/python3.10/site-packages/aiogram/bot/base.py", line 236, in request
    return await api.make_request(await self.get_session(), self.server, self.__token, method, data, files,
  File "/usr/local/lib/python3.10/site-packages/aiogram/bot/api.py", line 142, in make_request
    raise exceptions.NetworkError(f"aiohttp client throws an error: {e.__class__.__name__}: {e}")
aiogram.utils.exceptions.NetworkError: Aiohttp client throws an error: ClientConnectorError: Cannot connect to host api.telegram.org:443 ssl:default [Temporary failure in name resolution]
dispatcher.py [LINE:391] #ERROR    [2025-04-03 14:53:38,000]  Cause exception while getting updates.
Traceback (most recent call last):
  File "/usr/local/lib/python3.10/site-packages/aiohttp/connector.py", line 1155, in _create_direct_connection
    hosts = await asyncio.shield(host_resolved)
  File "/usr/local/lib/python3.10/site-packages/aiohttp/connector.py", line 874, in _resolve_host
    addrs = await self._resolver.resolve(host, port, family=self._family)
  File "/usr/local/lib/python3.10/site-packages/aiohttp/resolver.py", line 33, in resolve
    infos = await self._loop.getaddrinfo(
  File "/usr/local/lib/python3.10/asyncio/base_events.py", line 860, in getaddrinfo
    return await self.run_in_executor(
  File "/usr/local/lib/python3.10/concurrent/futures/thread.py", line 58, in run
    result = self.fn(*self.args, **self.kwargs)
  File "/usr/local/lib/python3.10/socket.py", line 955, in getaddrinfo
    for res in _socket.getaddrinfo(host, port, family, type, proto, flags):
socket.gaierror: [Errno -3] Temporary failure in name resolution

The above exception was the direct cause of the following exception:

Traceback (most recent call last):
  File "/usr/local/lib/python3.10/site-packages/aiogram/bot/api.py", line 139, in make_request
    async with session.post(url, data=req, **kwargs) as response:
  File "/usr/local/lib/python3.10/site-packages/aiohttp/client.py", line 1167, in __aenter__
    self._resp = await self._coro
  File "/usr/local/lib/python3.10/site-packages/aiohttp/client.py", line 562, in _request
    conn = await self._connector.connect(
  File "/usr/local/lib/python3.10/site-packages/aiohttp/connector.py", line 540, in connect
    proto = await self._create_connection(req, traces, timeout)
  File "/usr/local/lib/python3.10/site-packages/aiohttp/connector.py", line 901, in _create_connection
    _, proto = await self._create_direct_connection(req, traces, timeout)
  File "/usr/local/lib/python3.10/site-packages/aiohttp/connector.py", line 1169, in _create_direct_connection
    raise ClientConnectorError(req.connection_key, exc) from exc
aiohttp.client_exceptions.ClientConnectorError: Cannot connect to host api.telegram.org:443 ssl:default [Temporary failure in name resolution]

During handling of the above exception, another exception occurred:

Traceback (most recent call last):
  File "/usr/local/lib/python3.10/site-packages/aiogram/dispatcher/dispatcher.py", line 382, in start_polling
    updates = await self.bot.get_updates(
  File "/usr/local/lib/python3.10/site-packages/aiogram/bot/bot.py", line 110, in get_updates
    result = await self.request(api.Methods.GET_UPDATES, payload)
  File "/usr/local/lib/python3.10/site-packages/aiogram/bot/base.py", line 236, in request
    return await api.make_request(await self.get_session(), self.server, self.__token, method, data, files,
  File "/usr/local/lib/python3.10/site-packages/aiogram/bot/api.py", line 142, in make_request
    raise exceptions.NetworkError(f"aiohttp client throws an error: {e.__class__.__name__}: {e}")
aiogram.utils.exceptions.NetworkError: Aiohttp client throws an error: ClientConnectorError: Cannot connect to host api.telegram.org:443 ssl:default [Temporary failure in name resolution]
dispatcher.py [LINE:391] #ERROR    [2025-04-03 14:53:51,006]  Cause exception while getting updates.
Traceback (most recent call last):
  File "/usr/local/lib/python3.10/site-packages/aiohttp/connector.py", line 1155, in _create_direct_connection
    hosts = await asyncio.shield(host_resolved)
  File "/usr/local/lib/python3.10/site-packages/aiohttp/connector.py", line 874, in _resolve_host
    addrs = await self._resolver.resolve(host, port, family=self._family)
  File "/usr/local/lib/python3.10/site-packages/aiohttp/resolver.py", line 33, in resolve
    infos = await self._loop.getaddrinfo(
  File "/usr/local/lib/python3.10/asyncio/base_events.py", line 860, in getaddrinfo
    return await self.run_in_executor(
  File "/usr/local/lib/python3.10/concurrent/futures/thread.py", line 58, in run
    result = self.fn(*self.args, **self.kwargs)
  File "/usr/local/lib/python3.10/socket.py", line 955, in getaddrinfo
    for res in _socket.getaddrinfo(host, port, family, type, proto, flags):
socket.gaierror: [Errno -3] Temporary failure in name resolution

The above exception was the direct cause of the following exception:

Traceback (most recent call last):
  File "/usr/local/lib/python3.10/site-packages/aiogram/bot/api.py", line 139, in make_request
    async with session.post(url, data=req, **kwargs) as response:
  File "/usr/local/lib/python3.10/site-packages/aiohttp/client.py", line 1167, in __aenter__
    self._resp = await self._coro
  File "/usr/local/lib/python3.10/site-packages/aiohttp/client.py", line 562, in _request
    conn = await self._connector.connect(
  File "/usr/local/lib/python3.10/site-packages/aiohttp/connector.py", line 540, in connect
    proto = await self._create_connection(req, traces, timeout)
  File "/usr/local/lib/python3.10/site-packages/aiohttp/connector.py", line 901, in _create_connection
    _, proto = await self._create_direct_connection(req, traces, timeout)
  File "/usr/local/lib/python3.10/site-packages/aiohttp/connector.py", line 1169, in _create_direct_connection
    raise ClientConnectorError(req.connection_key, exc) from exc
aiohttp.client_exceptions.ClientConnectorError: Cannot connect to host api.telegram.org:443 ssl:default [Temporary failure in name resolution]

During handling of the above exception, another exception occurred:

Traceback (most recent call last):
  File "/usr/local/lib/python3.10/site-packages/aiogram/dispatcher/dispatcher.py", line 382, in start_polling
    updates = await self.bot.get_updates(
  File "/usr/local/lib/python3.10/site-packages/aiogram/bot/bot.py", line 110, in get_updates
    result = await self.request(api.Methods.GET_UPDATES, payload)
  File "/usr/local/lib/python3.10/site-packages/aiogram/bot/base.py", line 236, in request
    return await api.make_request(await self.get_session(), self.server, self.__token, method, data, files,
  File "/usr/local/lib/python3.10/site-packages/aiogram/bot/api.py", line 142, in make_request
    raise exceptions.NetworkError(f"aiohttp client throws an error: {e.__class__.__name__}: {e}")
aiogram.utils.exceptions.NetworkError: Aiohttp client throws an error: ClientConnectorError: Cannot connect to host api.telegram.org:443 ssl:default [Temporary failure in name resolution]
dispatcher.py [LINE:391] #ERROR    [2025-04-03 14:54:04,011]  Cause exception while getting updates.
Traceback (most recent call last):
  File "/usr/local/lib/python3.10/site-packages/aiohttp/connector.py", line 1155, in _create_direct_connection
    hosts = await asyncio.shield(host_resolved)
  File "/usr/local/lib/python3.10/site-packages/aiohttp/connector.py", line 874, in _resolve_host
    addrs = await self._resolver.resolve(host, port, family=self._family)
  File "/usr/local/lib/python3.10/site-packages/aiohttp/resolver.py", line 33, in resolve
    infos = await self._loop.getaddrinfo(
  File "/usr/local/lib/python3.10/asyncio/base_events.py", line 860, in getaddrinfo
    return await self.run_in_executor(
  File "/usr/local/lib/python3.10/concurrent/futures/thread.py", line 58, in run
    result = self.fn(*self.args, **self.kwargs)
  File "/usr/local/lib/python3.10/socket.py", line 955, in getaddrinfo
    for res in _socket.getaddrinfo(host, port, family, type, proto, flags):
socket.gaierror: [Errno -3] Temporary failure in name resolution

The above exception was the direct cause of the following exception:

Traceback (most recent call last):
  File "/usr/local/lib/python3.10/site-packages/aiogram/bot/api.py", line 139, in make_request
    async with session.post(url, data=req, **kwargs) as response:
  File "/usr/local/lib/python3.10/site-packages/aiohttp/client.py", line 1167, in __aenter__
    self._resp = await self._coro
  File "/usr/local/lib/python3.10/site-packages/aiohttp/client.py", line 562, in _request
    conn = await self._connector.connect(
  File "/usr/local/lib/python3.10/site-packages/aiohttp/connector.py", line 540, in connect
    proto = await self._create_connection(req, traces, timeout)
  File "/usr/local/lib/python3.10/site-packages/aiohttp/connector.py", line 901, in _create_connection
    _, proto = await self._create_direct_connection(req, traces, timeout)
  File "/usr/local/lib/python3.10/site-packages/aiohttp/connector.py", line 1169, in _create_direct_connection
    raise ClientConnectorError(req.connection_key, exc) from exc
aiohttp.client_exceptions.ClientConnectorError: Cannot connect to host api.telegram.org:443 ssl:default [Temporary failure in name resolution]

During handling of the above exception, another exception occurred:

Traceback (most recent call last):
  File "/usr/local/lib/python3.10/site-packages/aiogram/dispatcher/dispatcher.py", line 382, in start_polling
    updates = await self.bot.get_updates(
  File "/usr/local/lib/python3.10/site-packages/aiogram/bot/bot.py", line 110, in get_updates
    result = await self.request(api.Methods.GET_UPDATES, payload)
  File "/usr/local/lib/python3.10/site-packages/aiogram/bot/base.py", line 236, in request
    return await api.make_request(await self.get_session(), self.server, self.__token, method, data, files,
  File "/usr/local/lib/python3.10/site-packages/aiogram/bot/api.py", line 142, in make_request
    raise exceptions.NetworkError(f"aiohttp client throws an error: {e.__class__.__name__}: {e}")
aiogram.utils.exceptions.NetworkError: Aiohttp client throws an error: ClientConnectorError: Cannot connect to host api.telegram.org:443 ssl:default [Temporary failure in name resolution]
dispatcher.py [LINE:391] #ERROR    [2025-04-04 11:07:28,136]  Cause exception while getting updates.
Traceback (most recent call last):
  File "/usr/local/lib/python3.10/site-packages/aiogram/bot/api.py", line 139, in make_request
    async with session.post(url, data=req, **kwargs) as response:
  File "/usr/local/lib/python3.10/site-packages/aiohttp/client.py", line 1167, in __aenter__
    self._resp = await self._coro
  File "/usr/local/lib/python3.10/site-packages/aiohttp/client.py", line 586, in _request
    await resp.start(conn)
  File "/usr/local/lib/python3.10/site-packages/aiohttp/client_reqrep.py", line 905, in start
    message, payload = await protocol.read()  # type: ignore[union-attr]
  File "/usr/local/lib/python3.10/site-packages/aiohttp/streams.py", line 616, in read
    await self._waiter
aiohttp.client_exceptions.ClientOSError: [Errno 104] Connection reset by peer

During handling of the above exception, another exception occurred:

Traceback (most recent call last):
  File "/usr/local/lib/python3.10/site-packages/aiogram/dispatcher/dispatcher.py", line 382, in start_polling
    updates = await self.bot.get_updates(
  File "/usr/local/lib/python3.10/site-packages/aiogram/bot/bot.py", line 110, in get_updates
    result = await self.request(api.Methods.GET_UPDATES, payload)
  File "/usr/local/lib/python3.10/site-packages/aiogram/bot/base.py", line 236, in request
    return await api.make_request(await self.get_session(), self.server, self.__token, method, data, files,
  File "/usr/local/lib/python3.10/site-packages/aiogram/bot/api.py", line 142, in make_request
    raise exceptions.NetworkError(f"aiohttp client throws an error: {e.__class__.__name__}: {e}")
aiogram.utils.exceptions.NetworkError: Aiohttp client throws an error: ClientOSError: [Errno 104] Connection reset by peer
